
public class ExceptionsVideoExamples {

	public static void main(String[] args) {
		exceptionOne();
		
		exceptionTwo();
		System.out.println("In main"); // If there is an unhandled exception on lower levels of this stack call, this statement will not be printed
		
		exceptionThree();
		
		exceptionFour();
	}
	
	/**
	 * first exception example
	 */
	public static void exceptionOne() {
		int a, b = 6;
		 
		 try {
			 a = b / 0;
		 } catch(ArithmeticException ae) {
			 System.out.println("Arithmetic Exception in exceptionOne: " + ae.getMessage());
		 }
	}
	
	/**
	 * second exception example -- exception handled where it first occurs on the stack
	 */
	public static void exceptionTwo() {
		System.out.println("In exceptionTwo");
		exceptionTwoStackOne(); // If there is an unhandled exception on lower levels of this stack call, this statement will not be printed
		System.out.println("Not printed if there is an unhandled excpetion in exceptionTwoStackOne");
	}
	
	public static void exceptionTwoStackOne() {
		int num;
		System.out.println("In exceptionTwoStackOne");
		
		/**
		 * num = 1 / 0
		 * This line throws an exception. If the exception is not handled no code will be executed after this line; 
		 * this includes code below the function callers (written in functions up in the stack) that invoked "exceptionTwoStackOne": exceptionTwoStackOne() and exceptionTwo()
		 */

		// handled exception
		try {
			num = 1 / 0;
			System.out.println("This line doesn't get executed");
		 } catch (ArithmeticException ae) {
			 System.out.println("Arithmetic Exception in exceptionTwoStackOne: " + ae.getMessage());
		 }
	}
	
	
	/**
	 * third exception example -- exception handled on the caller of the function that throws the exception
	 */
	
	public static void exceptionThree() {
		System.out.println("In exceptionThree");
		
		// exception can be handled here since this is the caller of the function that throws the exception
		try {
			exceptionThreeStackOne(); 
			System.out.println("This line doesn't get executed");
		 } catch (ArithmeticException ae) {
			 System.out.println("Arithmetic Exception in exceptionThree: " + ae.getMessage());
		 }
	}
	
	public static void exceptionThreeStackOne() {
		int num;
		System.out.println("In exceptionThreeStackOne");
		
		/**
		 * num = 1 / 0
		 * This line throws an exception. If the exception is not handled no code will be executed after this line; 
		 * this includes code below the function callers (written in functions up in the stack) that invoked "exceptionTwoStackOne": exceptionTwoStackOne() and exceptionTwo()
		 */

		// unhandled exception -- handled up the call stack
		num = 1 / 0;
		System.out.println("This line doesn't get executed");
	}
	
	
	public static void exceptionFour() {
		System.out.println("In exceptionFour");
		
		
		// exception can be handled here since this is the caller of the function that throws the exception
		try {
			int num = 1 / 0;
			System.out.println("This line doesn't get executed");
		 } catch (ArithmeticException ae) {
			 System.out.println("Arithmetic Exception in exceptionFour: " + ae.getMessage());
		 } catch (RuntimeException re) {
			 System.out.println("Runtime Exception in exceptionFour: " + re.getMessage()); // this line only gets executed if exception is not of type ArithmeticException and is of type RuntimeException
		 } catch (Exception e) catch (Exception e) {
			 System.out.println("Exception in exceptionFour: " + e.getMessage()); // this line only gets executed if the exception is not of one of the  more specific exceptions on the above "catch" blocks 
		 }
	}
	
	

}
